<mujoco model="summit_xls">

    <compiler angle="radian" autolimits="true" meshdir = "./meshes"/>
    <statistic meansize="0.767828" extent="17.3945" center="-1.30273 -0.281443 0.819464" />

    <asset>
        <texture name="texplane" type="2d" builtin="checker" rgb1=".2 .3 .4" rgb2=".1 0.2 0.3" width="512" height="512"/>
        <material name="MatGnd" reflectance="0.5" texture="texplane" texrepeat="1 1" texuniform="true"/>
    </asset>
    
    <asset>
        <mesh name="summit_xls_chassis" file="bases/xls/summit_xls_chassis.stl" />
        <mesh name="summit_xls_chapas_inox_tapas" file="bases/xls/summit_xls_chapas_inox_tapas.stl" />
        <mesh name="robotnik_logo_chasis" file="bases/xls/robotnik_logo_chasis.stl" />
        <mesh name="summit_xls_omni_wheel_1" file="wheels/omni_wheel_1.stl" />
        <mesh name="summit_xls_omni_wheel_2" file="wheels/omni_wheel_2.stl" />
        <mesh name="structure_hokuyo" file="structures/structure_hokuyo.stl" />
    </asset>


    
    <worldbody>
        <!--/原点-->
        <body name="trace0" mocap="true">

            <site name="t0" type="sphere" size="0.03" rgba="1 0 0 0.5"/>

        </body>


        <!--light and environment-->
        <geom name="ground" pos="0 0 -0.01" rgba="0.25 0.26 0.25 1" size="12 12 2" type="plane" contype="1" conaffinity="1" />
        <light cutoff="4.0" diffuse="1 1 1" dir="-0.9 -0.9 -2.5" directional="true" exponent="20" pos="0.9 0.9 2.5" specular="0 0 0" />


        <!-- Summit XL Steel -->
        <body name="base_footprint" pos="0 0 -0.009">
            <joint type="free" stiffness="0" damping="0" frictionloss="0" armature="0"/>
            
            <!-- BASE_LINK -->
            <body name="base" pos="0 0 0.127">
                <inertial pos="0 0 0" quat="1 0 0 0" mass="125.0" diaginertia="1.391 6.853 6.125" />
                <geom type="mesh" rgba="0 0 0 1" mesh="summit_xls_chassis" contype="1" conaffinity="0" group="1"/>


                <!-- Wheels -->
                <body name="front_right_wheel_intermediate_link" pos="0.2225 -0.2045 0">
                    <inertial pos="0 0 0" quat="0.707107 0 0 0.707107" mass="6.5" diaginertia="0.0524193 0.0303095 0.0303095" />
                    <joint name="front_right_wheel_rolling_joint" pos="0 0 0" axis="0 1 0" />
                    <geom size="0.120 0.0435" quat="0.707107 0.707107 0 0" type="cylinder" rgba="0.2 0.2 0.2 0.5" contype="1" conaffinity="0" group="3" />
                    <geom type="mesh" mesh="summit_xls_omni_wheel_2" contype="0" conaffinity="0" group="2" rgba="0.2 0.2 0.2 1"/>
                

                    <body name="front_right_roller_0_link" pos="0.04385159698893431 0.0 0.011749999999999998">
                        <joint name="front_right_slipping_0_joint" type="hinge" pos="0 0 0" axis="-0.006296806022131382 0.0435 0.023499999999999997" damping="0.1" limited="false" actuatorfrclimited="false"/>
                        <inertial pos="0 0 0" quat="0.711549 0.711549 0 0 " mass="0.001" diaginertia="0.00001 0.00001 0.00001" />
                        <geom size="0.08" quat="1 0 0 0" type="sphere" rgba="0.2 0.2 0.2 1" contype="1" conaffinity="0" group="3"/>
                    </body>

                    <body name="front_right_roller_1_link" pos="0.03210159698893431 0.0 0.032101596988934306">
                        <joint name="front_right_slipping_1_joint" type="hinge" pos="0 0 0" axis="-0.01720319397786861 0.0435 0.017203193977868615" damping="0.1" limited="false" actuatorfrclimited="false"/>
                        <inertial pos="0 0 0" quat="0.711549 0.711549 0 0 " mass="0.001" diaginertia="0.00001 0.00001 0.00001" />
                        <geom size="0.08" quat="1 0 0 0" type="sphere" rgba="0.2 0.2 0.2 1" contype="1" conaffinity="0" group="3"/>
                    </body>

                    <body name="front_right_roller_2_link" pos="0.011750000000000005 0.0 0.0438515969889343">
                        <joint name="front_right_slipping_2_joint" type="hinge" pos="0 0 0" axis="-0.023500000000000004 0.0435 0.006296806022131389" damping="0.1" limited="false" actuatorfrclimited="false"/>
                        <inertial pos="0 0 0" quat="0.711549 0.711549 0 0 " mass="0.001" diaginertia="0.00001 0.00001 0.00001" />
                        <geom size="0.08" quat="1 0 0 0" type="sphere" rgba="0.2 0.2 0.2 1" contype="1" conaffinity="0" group="3"/>
                    </body>

                    <body name="front_right_roller_3_link" pos="-0.011749999999999993 0.0 0.04385159698893431">
                        <joint name="front_right_slipping_3_joint" type="hinge" pos="0 0 0" axis="-0.023499999999999993 0.0435 -0.006296806022131382" damping="0.1" limited="false" actuatorfrclimited="false"/>
                        <inertial pos="0 0 0" quat="0.711549 0.711549 0 0 " mass="0.001" diaginertia="0.00001 0.00001 0.00001" />
                        <geom size="0.08" quat="1 0 0 0" type="sphere" rgba="0.2 0.2 0.2 1" contype="1" conaffinity="0" group="3"/>
                    </body>

                    <body name="front_right_roller_4_link" pos="-0.0321015969889343 0.0 0.03210159698893432">
                        <joint name="front_right_slipping_4_joint" type="hinge" pos="0 0 0" axis="-0.01720319397786862 0.0435 -0.0172031939778686" damping="0.1" limited="false" actuatorfrclimited="false"/>
                        <inertial pos="0 0 0" quat="0.711549 0.711549 0 0 " mass="0.001" diaginertia="0.00001 0.00001 0.00001" />
                        <geom size="0.08" quat="1 0 0 0" type="sphere" rgba="0.2 0.2 0.2 1" contype="1" conaffinity="0" group="3"/>
                    </body>

                    <body name="front_right_roller_5_link" pos="-0.0438515969889343 0.0 0.011750000000000012">
                        <joint name="front_right_slipping_5_joint" type="hinge" pos="0 0 0" axis="-0.006296806022131389 0.0435 -0.02350000000000001" damping="0.1" limited="false" actuatorfrclimited="false"/>
                        <inertial pos="0 0 0" quat="0.711549 0.711549 0 0 " mass="0.001" diaginertia="0.00001 0.00001 0.00001" />
                        <geom size="0.08" quat="1 0 0 0" type="sphere" rgba="0.2 0.2 0.2 1" contype="1" conaffinity="0" group="3"/>
                    </body>

                    <body name="front_right_roller_6_link" pos="-0.043851596988934316 0.0 -0.011749999999999991">
                        <joint name="front_right_slipping_6_joint" type="hinge" pos="0 0 0" axis="0.006296806022131375 0.0435 -0.023499999999999993" damping="0.1" limited="false" actuatorfrclimited="false"/>
                        <inertial pos="0 0 0" quat="0.711549 0.711549 0 0 " mass="0.001" diaginertia="0.00001 0.00001 0.00001" />
                        <geom size="0.08" quat="1 0 0 0" type="sphere" rgba="0.2 0.2 0.2 1" contype="1" conaffinity="0" group="3"/>
                    </body>

                    <body name="front_right_roller_7_link" pos="-0.03210159698893432 0.0 -0.03210159698893429">
                        <joint name="front_right_slipping_7_joint" type="hinge" pos="0 0 0" axis="0.017203193977868604 0.0435 -0.017203193977868618" damping="0.1" limited="false" actuatorfrclimited="false"/>
                        <inertial pos="0 0 0" quat="0.711549 0.711549 0 0 " mass="0.001" diaginertia="0.00001 0.00001 0.00001" />
                        <geom size="0.08" quat="1 0 0 0" type="sphere" rgba="0.2 0.2 0.2 1" contype="1" conaffinity="0" group="3"/>
                    </body>

                    <body name="front_right_roller_8_link" pos="-0.011750000000000014 0.0 -0.0438515969889343">
                        <joint name="front_right_slipping_8_joint" type="hinge" pos="0 0 0" axis="0.023500000000000014 0.0435 -0.006296806022131396" damping="0.1" limited="false" actuatorfrclimited="false"/>
                        <inertial pos="0 0 0" quat="0.711549 0.711549 0 0 " mass="0.001" diaginertia="0.00001 0.00001 0.00001" />
                        <geom size="0.08" quat="1 0 0 0" type="sphere" rgba="0.2 0.2 0.2 1" contype="1" conaffinity="0" group="3"/>
                    </body>

                    <body name="front_right_roller_9_link" pos="0.01174999999999998 0.0 -0.043851596988934316">
                        <joint name="front_right_slipping_9_joint" type="hinge" pos="0 0 0" axis="0.023499999999999976 0.0435 0.006296806022131368" damping="0.1" limited="false" actuatorfrclimited="false"/>
                        <inertial pos="0 0 0" quat="0.711549 0.711549 0 0 " mass="0.001" diaginertia="0.00001 0.00001 0.00001" />
                        <geom size="0.08" quat="1 0 0 0" type="sphere" rgba="0.2 0.2 0.2 1" contype="1" conaffinity="0" group="3"/>
                    </body>

                    <body name="front_right_roller_10_link" pos="0.032101596988934285 0.0 -0.032101596988934326">
                        <joint name="front_right_slipping_10_joint" type="hinge" pos="0 0 0" axis="0.017203193977868635 0.0435 0.01720319397786861" damping="0.1" limited="false" actuatorfrclimited="false"/>
                        <inertial pos="0 0 0" quat="0.711549 0.711549 0 0 " mass="0.001" diaginertia="0.00001 0.00001 0.00001" />
                        <geom size="0.08" quat="1 0 0 0" type="sphere" rgba="0.2 0.2 0.2 1" contype="1" conaffinity="0" group="3"/>
                    </body>

                    <body name="front_right_roller_11_link" pos="0.0438515969889343 0.0 -0.01175000000000001">
                        <joint name="front_right_slipping_11_joint" type="hinge" pos="0 0 0" axis="0.006296806022131396 0.0435 0.02350000000000002" damping="0.1" limited="false" actuatorfrclimited="false"/>
                        <inertial pos="0 0 0" quat="0.711549 0.711549 0 0 " mass="0.001" diaginertia="0.00001 0.00001 0.00001" />
                        <geom size="0.08" quat="1 0 0 0" type="sphere" rgba="0.2 0.2 0.2 1" contype="1" conaffinity="0" group="3"/>
                    </body>
                </body>

                <body name="front_left_wheel_intermediate_link" pos="0.2225 0.2045 0">
                    <inertial pos="0 0 0" quat="0.707107 0 0 0.707107" mass="6.5" diaginertia="0.0524193 0.0303095 0.0303095" />
                    <joint name="front_left_wheel_rolling_joint" pos="0 0 0" axis="0 1 0" />
                    <geom size="0.120 0.0435" quat="0.707107 0.707107 0 0" type="cylinder" rgba="0.2 0.2 0.2 0.5" contype="1" conaffinity="0" group="3"/>
                    <geom type="mesh" mesh="summit_xls_omni_wheel_1" contype="0" conaffinity="0" group="2" rgba="0.2 0.2 0.2 1"/>


                    <body name="front_left_roller_0_link" pos="0.0438515969889343 0.0 -0.01175000000000001">
                        <joint name="front_left_slipping_0_joint" type="hinge" pos="0 0 0" axis="-0.006296806022131396 0.0435 -0.02350000000000002" damping="0.1" limited="false" actuatorfrclimited="false"/>
                        <inertial pos="0 0 0" quat="0.711549 0.711549 0 0 " mass="0.001" diaginertia="0.00001 0.00001 0.00001" />
                        <geom size="0.08" quat="1 0 0 0" type="sphere" rgba="0.2 0.2 0.2 1" contype="1" conaffinity="0" group="3"/>
                    </body>

                    <body name="front_left_roller_1_link" pos="0.04385159698893431 0.0 0.011749999999999998">
                        <joint name="front_left_slipping_1_joint" type="hinge" pos="0 0 0" axis="0.006296806022131382 0.0435 -0.023499999999999997" damping="0.1" limited="false" actuatorfrclimited="false"/>
                        <inertial pos="0 0 0" quat="0.711549 0.711549 0 0 " mass="0.001" diaginertia="0.00001 0.00001 0.00001" />
                        <geom size="0.08" quat="1 0 0 0" type="sphere" rgba="0.2 0.2 0.2 1" contype="1" conaffinity="0" group="3"/>
                    </body>

                    <body name="front_left_roller_2_link" pos="0.03210159698893431 0.0 0.032101596988934306">
                        <joint name="front_left_slipping_2_joint" type="hinge" pos="0 0 0" axis="0.01720319397786861 0.0435 -0.017203193977868615" damping="0.1" limited="false" actuatorfrclimited="false"/>
                        <inertial pos="0 0 0" quat="0.711549 0.711549 0 0 " mass="0.001" diaginertia="0.00001 0.00001 0.00001" />
                        <geom size="0.08" quat="1 0 0 0" type="sphere" rgba="0.2 0.2 0.2 1" contype="1" conaffinity="0" group="3"/>
                    </body>

                    <body name="front_left_roller_3_link" pos="0.011750000000000005 0.0 0.0438515969889343">
                        <joint name="front_left_slipping_3_joint" type="hinge" pos="0 0 0" axis="0.023500000000000004 0.0435 -0.006296806022131389" damping="0.1" limited="false" actuatorfrclimited="false"/>
                        <inertial pos="0 0 0" quat="0.711549 0.711549 0 0 " mass="0.001" diaginertia="0.00001 0.00001 0.00001" />
                        <geom size="0.08" quat="1 0 0 0" type="sphere" rgba="0.2 0.2 0.2 1" contype="1" conaffinity="0" group="3"/>
                    </body>

                    <body name="front_left_roller_4_link" pos="-0.011749999999999993 0.0 0.04385159698893431">
                        <joint name="front_left_slipping_4_joint" type="hinge" pos="0 0 0" axis="0.023499999999999993 0.0435 0.006296806022131382" damping="0.1" limited="false" actuatorfrclimited="false"/>
                        <inertial pos="0 0 0" quat="0.711549 0.711549 0 0 " mass="0.001" diaginertia="0.00001 0.00001 0.00001" />
                        <geom size="0.08" quat="1 0 0 0" type="sphere" rgba="0.2 0.2 0.2 1" contype="1" conaffinity="0" group="3"/>
                    </body>

                    <body name="front_left_roller_5_link" pos="-0.0321015969889343 0.0 0.03210159698893432">
                        <joint name="front_left_slipping_5_joint" type="hinge" pos="0 0 0" axis="0.01720319397786862 0.0435 0.0172031939778686" damping="0.1" limited="false" actuatorfrclimited="false"/>
                        <inertial pos="0 0 0" quat="0.711549 0.711549 0 0 " mass="0.001" diaginertia="0.00001 0.00001 0.00001" />
                        <geom size="0.08" quat="1 0 0 0" type="sphere" rgba="0.2 0.2 0.2 1" contype="1" conaffinity="0" group="3"/>
                    </body>

                    <body name="front_left_roller_6_link" pos="-0.0438515969889343 0.0 0.01175000000000001">
                        <joint name="front_left_slipping_6_joint" type="hinge" pos="0 0 0" axis="0.006296806022131389 0.0435 0.02350000000000001" damping="0.1" limited="false" actuatorfrclimited="false"/>
                        <inertial pos="0 0 0" quat="0.711549 0.711549 0 0 " mass="0.001" diaginertia="0.00001 0.00001 0.00001" />
                        <geom size="0.08" quat="1 0 0 0" type="sphere" rgba="0.2 0.2 0.2 1" contype="1" conaffinity="0" group="3"/>
                    </body>

                    <body name="front_left_roller_7_link" pos="-0.043851596988934316 0.0 -0.01174999999999999">
                        <joint name="front_left_slipping_7_joint" type="hinge" pos="0 0 0" axis="-0.006296806022131375 0.0435 0.023499999999999993" damping="0.1" limited="false" actuatorfrclimited="false"/>
                        <inertial pos="0 0 0" quat="0.711549 0.711549 0 0 " mass="0.001" diaginertia="0.00001 0.00001 0.00001" />
                        <geom size="0.08" quat="1 0 0 0" type="sphere" rgba="0.2 0.2 0.2 1" contype="1" conaffinity="0" group="3"/>
                    </body>

                    <body name="front_left_roller_8_link" pos="-0.03210159698893432 0.0 -0.03210159698893429">
                        <joint name="front_left_slipping_8_joint" type="hinge" pos="0 0 0" axis="-0.017203193977868604 0.0435 0.017203193977868618" damping="0.1" limited="false" actuatorfrclimited="false"/>
                        <inertial pos="0 0 0" quat="0.711549 0.711549 0 0 " mass="0.001" diaginertia="0.00001 0.00001 0.00001" />
                        <geom size="0.08" quat="1 0 0 0" type="sphere" rgba="0.2 0.2 0.2 1" contype="1" conaffinity="0" group="3"/>
                    </body>

                    <body name="front_left_roller_9_link" pos="-0.011750000000000016 0.0 -0.0438515969889343">
                        <joint name="front_left_slipping_9_joint" type="hinge" pos="0 0 0" axis="-0.023500000000000014 0.0435 0.006296806022131396" damping="0.1" limited="false" actuatorfrclimited="false"/>
                        <inertial pos="0 0 0" quat="0.711549 0.711549 0 0 " mass="0.001" diaginertia="0.00001 0.00001 0.00001" />
                        <geom size="0.08" quat="1 0 0 0" type="sphere" rgba="0.2 0.2 0.2 1" contype="1" conaffinity="0" group="3"/>
                    </body>

                    <body name="front_left_roller_10_link" pos="0.011749999999999981 0.0 -0.043851596988934316">
                        <joint name="front_left_slipping_10_joint" type="hinge" pos="0 0 0" axis="-0.023499999999999976 0.0435 -0.006296806022131368" damping="0.1" limited="false" actuatorfrclimited="false"/>
                        <inertial pos="0 0 0" quat="0.711549 0.711549 0 0 " mass="0.001" diaginertia="0.00001 0.00001 0.00001" />
                        <geom size="0.08" quat="1 0 0 0" type="sphere" rgba="0.2 0.2 0.2 1" contype="1" conaffinity="0" group="3"/>
                    </body>

                    <body name="front_left_roller_11_link" pos="0.032101596988934285 0.0 -0.032101596988934326">
                        <joint name="front_left_slipping_11_joint" type="hinge" pos="0 0 0" axis="-0.017203193977868635 0.0435 -0.01720319397786861" damping="0.1" limited="false" actuatorfrclimited="false"/>
                        <inertial pos="0 0 0" quat="0.711549 0.711549 0 0 " mass="0.001" diaginertia="0.00001 0.00001 0.00001" />
                        <geom size="0.08" quat="1 0 0 0" type="sphere" rgba="0.2 0.2 0.2 1" contype="1" conaffinity="0" group="3"/>
                    </body>
                </body>

                <body name="back_right_wheel_intermediate_link" pos="-0.2225 -0.2045 0">
                    <inertial pos="0 0 0" quat="0.707107 0 0 0.707107" mass="6.5" diaginertia="0.0524193 0.0303095 0.0303095" />
                    <joint name="back_right_wheel_rolling_joint" pos="0 0 0" axis="0 1 0" />
                    <geom size="0.120 0.0435" quat="0.707107 0.707107 0 0" type="cylinder" rgba="0.2 0.2 0.2 0.5" contype="1" conaffinity="0" group="3"/>
                    <geom type="mesh" mesh="summit_xls_omni_wheel_1" contype="0" conaffinity="0" group="2" rgba="0.2 0.2 0.2 1"/>


                    <body name="back_right_roller_0_link" pos="0.0438515969889343 0.0 -0.01175000000000001">
                        <joint name="back_right_slipping_0_joint" type="hinge" pos="0 0 0" axis="-0.006296806022131396 0.0435 -0.02350000000000002" damping="0.1" limited="false" actuatorfrclimited="false"/>
                        <inertial pos="0 0 0" quat="0.711549 0.711549 0 0 " mass="0.001" diaginertia="0.00001 0.00001 0.00001" />
                        <geom size="0.08" quat="1 0 0 0" type="sphere" rgba="0.2 0.2 0.2 1" contype="1" conaffinity="0" group="3"/>
                    </body>

                    <body name="back_right_roller_1_link" pos="0.04385159698893431 0.0 0.011749999999999998">
                        <joint name="back_right_slipping_1_joint" type="hinge" pos="0 0 0" axis="0.006296806022131382 0.0435 -0.023499999999999997" damping="0.1" limited="false" actuatorfrclimited="false"/>
                        <inertial pos="0 0 0" quat="0.711549 0.711549 0 0 " mass="0.001" diaginertia="0.00001 0.00001 0.00001" />
                        <geom size="0.08" quat="1 0 0 0" type="sphere" rgba="0.2 0.2 0.2 1" contype="1" conaffinity="0" group="3"/>
                    </body>

                    <body name="back_right_roller_2_link" pos="0.03210159698893431 0.0 0.032101596988934306">
                        <joint name="back_right_slipping_2_joint" type="hinge" pos="0 0 0" axis="0.01720319397786861 0.0435 -0.017203193977868615" damping="0.1" limited="false" actuatorfrclimited="false"/>
                        <inertial pos="0 0 0" quat="0.711549 0.711549 0 0 " mass="0.001" diaginertia="0.00001 0.00001 0.00001" />
                        <geom size="0.08" quat="1 0 0 0" type="sphere" rgba="0.2 0.2 0.2 1" contype="1" conaffinity="0" group="3"/>
                    </body>

                    <body name="back_right_roller_3_link" pos="0.011750000000000005 0.0 0.0438515969889343">
                        <joint name="back_right_slipping_3_joint" type="hinge" pos="0 0 0" axis="0.023500000000000004 0.0435 -0.006296806022131389" damping="0.1" limited="false" actuatorfrclimited="false"/>
                        <inertial pos="0 0 0" quat="0.711549 0.711549 0 0 " mass="0.001" diaginertia="0.00001 0.00001 0.00001" />
                        <geom size="0.08" quat="1 0 0 0" type="sphere" rgba="0.2 0.2 0.2 1" contype="1" conaffinity="0" group="3"/>
                    </body>

                    <body name="back_right_roller_4_link" pos="-0.011749999999999993 0.0 0.04385159698893431">
                        <joint name="back_right_slipping_4_joint" type="hinge" pos="0 0 0" axis="0.023499999999999993 0.0435 0.006296806022131382" damping="0.1" limited="false" actuatorfrclimited="false"/>
                        <inertial pos="0 0 0" quat="0.711549 0.711549 0 0 " mass="0.001" diaginertia="0.00001 0.00001 0.00001" />
                        <geom size="0.08" quat="1 0 0 0" type="sphere" rgba="0.2 0.2 0.2 1" contype="1" conaffinity="0" group="3"/>
                    </body>

                    <body name="back_right_roller_5_link" pos="-0.0321015969889343 0.0 0.03210159698893432">
                        <joint name="back_right_slipping_5_joint" type="hinge" pos="0 0 0" axis="0.01720319397786862 0.0435 0.0172031939778686" damping="0.1" limited="false" actuatorfrclimited="false"/>
                        <inertial pos="0 0 0" quat="0.711549 0.711549 0 0 " mass="0.001" diaginertia="0.00001 0.00001 0.00001" />
                        <geom size="0.08" quat="1 0 0 0" type="sphere" rgba="0.2 0.2 0.2 1" contype="1" conaffinity="0" group="3"/>
                    </body>

                    <body name="back_right_roller_6_link" pos="-0.0438515969889343 0.0 0.01175000000000001">
                        <joint name="back_right_slipping_6_joint" type="hinge" pos="0 0 0" axis="0.006296806022131389 0.0435 0.02350000000000001" damping="0.1" limited="false" actuatorfrclimited="false"/>
                        <inertial pos="0 0 0" quat="0.711549 0.711549 0 0 " mass="0.001" diaginertia="0.00001 0.00001 0.00001" />
                        <geom size="0.08" quat="1 0 0 0" type="sphere" rgba="0.2 0.2 0.2 1" contype="1" conaffinity="0" group="3"/>
                    </body>

                    <body name="back_right_roller_7_link" pos="-0.043851596988934316 0.0 -0.01174999999999999">
                        <joint name="back_right_slipping_7_joint" type="hinge" pos="0 0 0" axis="-0.006296806022131375 0.0435 0.023499999999999993" damping="0.1" limited="false" actuatorfrclimited="false"/>
                        <inertial pos="0 0 0" quat="0.711549 0.711549 0 0 " mass="0.001" diaginertia="0.00001 0.00001 0.00001" />
                        <geom size="0.08" quat="1 0 0 0" type="sphere" rgba="0.2 0.2 0.2 1" contype="1" conaffinity="0" group="3"/>
                    </body>

                    <body name="back_right_roller_8_link" pos="-0.03210159698893432 0.0 -0.03210159698893429">
                        <joint name="back_right_slipping_8_joint" type="hinge" pos="0 0 0" axis="-0.017203193977868604 0.0435 0.017203193977868618" damping="0.1" limited="false" actuatorfrclimited="false"/>
                        <inertial pos="0 0 0" quat="0.711549 0.711549 0 0 " mass="0.001" diaginertia="0.00001 0.00001 0.00001" />
                        <geom size="0.08" quat="1 0 0 0" type="sphere" rgba="0.2 0.2 0.2 1" contype="1" conaffinity="0" group="3"/>
                    </body>

                    <body name="back_right_roller_9_link" pos="-0.011750000000000016 0.0 -0.0438515969889343">
                        <joint name="back_right_slipping_9_joint" type="hinge" pos="0 0 0" axis="-0.023500000000000014 0.0435 0.006296806022131396" damping="0.1" limited="false" actuatorfrclimited="false"/>
                        <inertial pos="0 0 0" quat="0.711549 0.711549 0 0 " mass="0.001" diaginertia="0.00001 0.00001 0.00001" />
                        <geom size="0.08" quat="1 0 0 0" type="sphere" rgba="0.2 0.2 0.2 1" contype="1" conaffinity="0" group="3"/>
                    </body>

                    <body name="back_right_roller_10_link" pos="0.011749999999999981 0.0 -0.043851596988934316">
                        <joint name="back_right_slipping_10_joint" type="hinge" pos="0 0 0" axis="-0.023499999999999976 0.0435 -0.006296806022131368" damping="0.1" limited="false" actuatorfrclimited="false"/>
                        <inertial pos="0 0 0" quat="0.711549 0.711549 0 0 " mass="0.001" diaginertia="0.00001 0.00001 0.00001" />
                        <geom size="0.08" quat="1 0 0 0" type="sphere" rgba="0.2 0.2 0.2 1" contype="1" conaffinity="0" group="3"/>
                    </body>

                    <body name="back_right_roller_11_link" pos="0.032101596988934285 0.0 -0.032101596988934326">
                        <joint name="back_right_slipping_11_joint" type="hinge" pos="0 0 0" axis="-0.017203193977868635 0.0435 -0.01720319397786861" damping="0.1" limited="false" actuatorfrclimited="false"/>
                        <inertial pos="0 0 0" quat="0.711549 0.711549 0 0 " mass="0.001" diaginertia="0.00001 0.00001 0.00001" />
                        <geom size="0.08" quat="1 0 0 0" type="sphere" rgba="0.2 0.2 0.2 1" contype="1" conaffinity="0" group="3"/>
                    </body>
                </body>

                <body name="back_left_wheel_intermediate_link" pos="-0.2225 0.2045 0">
                    <inertial pos="0 0 0" quat="0.707107 0 0 0.707107" mass="6.5" diaginertia="0.0524193 0.0303095 0.0303095" />
                    <joint name="back_left_wheel_rolling_joint" pos="0 0 0" axis="0 1 0" />
                    <geom size="0.120 0.0435" quat="0.707107 0.707107 0 0" type="cylinder" rgba="0.2 0.2 0.2 0.5" contype="1" conaffinity="0" group="3"/>
                    <geom type="mesh" mesh="summit_xls_omni_wheel_2" contype="0" conaffinity="0" group="2" rgba="0.2 0.2 0.2 1"/>


                    <body name="back_left_roller_0_link" pos="0.04385159698893431 0.0 0.011749999999999998">
                        <joint name="back_left_slipping_0_joint" type="hinge" pos="0 0 0" axis="-0.006296806022131382 0.0435 0.023499999999999997" damping="0.1" limited="false" actuatorfrclimited="false"/>
                        <inertial pos="0 0 0" quat="0.711549 0.711549 0 0 " mass="0.001" diaginertia="0.00001 0.00001 0.00001" />
                        <geom size="0.08" quat="1 0 0 0" type="sphere" rgba="0.2 0.2 0.2 1" contype="1" conaffinity="0" group="3"/>
                    </body>

                    <body name="back_left_roller_1_link" pos="0.03210159698893431 0.0 0.032101596988934306">
                        <joint name="back_left_slipping_1_joint" type="hinge" pos="0 0 0" axis="-0.01720319397786861 0.0435 0.017203193977868615" damping="0.1" limited="false" actuatorfrclimited="false"/>
                        <inertial pos="0 0 0" quat="0.711549 0.711549 0 0 " mass="0.001" diaginertia="0.00001 0.00001 0.00001" />
                        <geom size="0.08" quat="1 0 0 0" type="sphere" rgba="0.2 0.2 0.2 1" contype="1" conaffinity="0" group="3"/>
                    </body>

                    <body name="back_left_roller_2_link" pos="0.011750000000000005 0.0 0.0438515969889343">
                        <joint name="back_left_slipping_2_joint" type="hinge" pos="0 0 0" axis="-0.023500000000000004 0.0435 0.006296806022131389" damping="0.1" limited="false" actuatorfrclimited="false"/>
                        <inertial pos="0 0 0" quat="0.711549 0.711549 0 0 " mass="0.001" diaginertia="0.00001 0.00001 0.00001" />
                        <geom size="0.08" quat="1 0 0 0" type="sphere" rgba="0.2 0.2 0.2 1" contype="1" conaffinity="0" group="3"/>
                    </body>

                    <body name="back_left_roller_3_link" pos="-0.011749999999999993 0.0 0.04385159698893431">
                        <joint name="back_left_slipping_3_joint" type="hinge" pos="0 0 0" axis="-0.023499999999999993 0.0435 -0.006296806022131382" damping="0.1" limited="false" actuatorfrclimited="false"/>
                        <inertial pos="0 0 0" quat="0.711549 0.711549 0 0 " mass="0.001" diaginertia="0.00001 0.00001 0.00001" />
                        <geom size="0.08" quat="1 0 0 0" type="sphere" rgba="0.2 0.2 0.2 1" contype="1" conaffinity="0" group="3"/>
                    </body>

                    <body name="back_left_roller_4_link" pos="-0.0321015969889343 0.0 0.03210159698893432">
                        <joint name="back_left_slipping_4_joint" type="hinge" pos="0 0 0" axis="-0.01720319397786862 0.0435 -0.0172031939778686" damping="0.1" limited="false" actuatorfrclimited="false"/>
                        <inertial pos="0 0 0" quat="0.711549 0.711549 0 0 " mass="0.001" diaginertia="0.00001 0.00001 0.00001" />
                        <geom size="0.08" quat="1 0 0 0" type="sphere" rgba="0.2 0.2 0.2 1" contype="1" conaffinity="0" group="3"/>
                    </body>

                    <body name="back_left_roller_5_link" pos="-0.0438515969889343 0.0 0.011750000000000012">
                        <joint name="back_left_slipping_5_joint" type="hinge" pos="0 0 0" axis="-0.006296806022131389 0.0435 -0.02350000000000001" damping="0.1" limited="false" actuatorfrclimited="false"/>
                        <inertial pos="0 0 0" quat="0.711549 0.711549 0 0 " mass="0.001" diaginertia="0.00001 0.00001 0.00001" />
                        <geom size="0.08" quat="1 0 0 0" type="sphere" rgba="0.2 0.2 0.2 1" contype="1" conaffinity="0" group="3"/>
                    </body>

                    <body name="back_left_roller_6_link" pos="-0.043851596988934316 0.0 -0.011749999999999991">
                        <joint name="back_left_slipping_6_joint" type="hinge" pos="0 0 0" axis="0.006296806022131375 0.0435 -0.023499999999999993" damping="0.1" limited="false" actuatorfrclimited="false"/>
                        <inertial pos="0 0 0" quat="0.711549 0.711549 0 0 " mass="0.001" diaginertia="0.00001 0.00001 0.00001" />
                        <geom size="0.08" quat="1 0 0 0" type="sphere" rgba="0.2 0.2 0.2 1" contype="1" conaffinity="0" group="3"/>
                    </body>

                    <body name="back_left_roller_7_link" pos="-0.03210159698893432 0.0 -0.03210159698893429">
                        <joint name="back_left_slipping_7_joint" type="hinge" pos="0 0 0" axis="0.017203193977868604 0.0435 -0.017203193977868618" damping="0.1" limited="false" actuatorfrclimited="false"/>
                        <inertial pos="0 0 0" quat="0.711549 0.711549 0 0 " mass="0.001" diaginertia="0.00001 0.00001 0.00001" />
                        <geom size="0.08" quat="1 0 0 0" type="sphere" rgba="0.2 0.2 0.2 1" contype="1" conaffinity="0" group="3"/>
                    </body>

                    <body name="back_left_roller_8_link" pos="-0.011750000000000014 0.0 -0.0438515969889343">
                        <joint name="back_left_slipping_8_joint" type="hinge" pos="0 0 0" axis="0.023500000000000014 0.0435 -0.006296806022131396" damping="0.1" limited="false" actuatorfrclimited="false"/>
                        <inertial pos="0 0 0" quat="0.711549 0.711549 0 0 " mass="0.001" diaginertia="0.00001 0.00001 0.00001" />
                        <geom size="0.08" quat="1 0 0 0" type="sphere" rgba="0.2 0.2 0.2 1" contype="1" conaffinity="0" group="3"/>
                    </body>

                    <body name="back_left_roller_9_link" pos="0.01174999999999998 0.0 -0.043851596988934316">
                        <joint name="back_left_slipping_9_joint" type="hinge" pos="0 0 0" axis="0.023499999999999976 0.0435 0.006296806022131368" damping="0.1" limited="false" actuatorfrclimited="false"/>
                        <inertial pos="0 0 0" quat="0.711549 0.711549 0 0 " mass="0.001" diaginertia="0.00001 0.00001 0.00001" />
                        <geom size="0.08" quat="1 0 0 0" type="sphere" rgba="0.2 0.2 0.2 1" contype="1" conaffinity="0" group="3"/>
                    </body>

                    <body name="back_left_roller_10_link" pos="0.032101596988934285 0.0 -0.032101596988934326">
                        <joint name="back_left_slipping_10_joint" type="hinge" pos="0 0 0" axis="0.017203193977868635 0.0435 0.01720319397786861" damping="0.1" limited="false" actuatorfrclimited="false"/>
                        <inertial pos="0 0 0" quat="0.711549 0.711549 0 0 " mass="0.001" diaginertia="0.00001 0.00001 0.00001" />
                        <geom size="0.08" quat="1 0 0 0" type="sphere" rgba="0.2 0.2 0.2 1" contype="1" conaffinity="0" group="3"/>
                    </body>

                    <body name="back_left_roller_11_link" pos="0.0438515969889343 0.0 -0.01175000000000001">
                        <joint name="back_left_slipping_11_joint" type="hinge" pos="0 0 0" axis="0.006296806022131396 0.0435 0.02350000000000002" damping="0.1" limited="false" actuatorfrclimited="false"/>
                        <inertial pos="0 0 0" quat="0.711549 0.711549 0 0 " mass="0.001" diaginertia="0.00001 0.00001 0.00001" />
                        <geom size="0.08" quat="1 0 0 0" type="sphere" rgba="0.2 0.2 0.2 1" contype="1" conaffinity="0" group="3"/>
                    </body>
                </body>
        
            </body>

        </body>

    </worldbody>

    <actuator>
        <motor name="front_right_wheel_rolling_joint" joint="front_right_wheel_rolling_joint" ctrlrange="-10 10"/>
        <motor name="front_left_wheel_rolling_joint"  joint="front_left_wheel_rolling_joint"  ctrlrange="-10 10"/>
        <motor name="back_right_wheel_rolling_joint"  joint="back_right_wheel_rolling_joint"  ctrlrange="-10 10"/>
        <motor name="back_left_wheel_rolling_joint"   joint="back_left_wheel_rolling_joint"   ctrlrange="-10 10"/>
    </actuator>

</mujoco>